[2024-02-17T18:59:58.019+0000] {taskinstance.py:1956} INFO - Dependencies all met for dep_context=non-requeueable deps ti=<TaskInstance: src_to_data_platform.email_on_failure manual__2024-02-17T18:59:48.520418+00:00 [queued]>
[2024-02-17T18:59:58.040+0000] {taskinstance.py:1956} INFO - Dependencies all met for dep_context=requeueable deps ti=<TaskInstance: src_to_data_platform.email_on_failure manual__2024-02-17T18:59:48.520418+00:00 [queued]>
[2024-02-17T18:59:58.043+0000] {taskinstance.py:2170} INFO - Starting attempt 1 of 2
[2024-02-17T18:59:58.101+0000] {taskinstance.py:2191} INFO - Executing <Task(EmailOperator): email_on_failure> on 2024-02-17 18:59:48.520418+00:00
[2024-02-17T18:59:58.121+0000] {standard_task_runner.py:60} INFO - Started process 95 to run task
[2024-02-17T18:59:58.126+0000] {standard_task_runner.py:87} INFO - Running: ['***', 'tasks', 'run', 'src_to_data_platform', 'email_on_failure', 'manual__2024-02-17T18:59:48.520418+00:00', '--job-id', '56', '--raw', '--subdir', 'DAGS_FOLDER/src_to_platform_dag.py', '--cfg-path', '/tmp/tmp38yxcqr_']
[2024-02-17T18:59:58.131+0000] {standard_task_runner.py:88} INFO - Job 56: Subtask email_on_failure
[2024-02-17T18:59:58.299+0000] {task_command.py:423} INFO - Running <TaskInstance: src_to_data_platform.email_on_failure manual__2024-02-17T18:59:48.520418+00:00 [running]> on host 8bc74b80747f
[2024-02-17T18:59:58.477+0000] {taskinstance.py:2480} INFO - Exporting env vars: AIRFLOW_CTX_DAG_OWNER='***' AIRFLOW_CTX_DAG_ID='src_to_data_platform' AIRFLOW_CTX_TASK_ID='email_on_failure' AIRFLOW_CTX_EXECUTION_DATE='2024-02-17T18:59:48.520418+00:00' AIRFLOW_CTX_TRY_NUMBER='1' AIRFLOW_CTX_DAG_RUN_ID='manual__2024-02-17T18:59:48.520418+00:00'
[2024-02-17T18:59:58.502+0000] {warnings.py:109} WARNING - /home/***/.local/lib/python3.8/site-packages/***/utils/email.py:154: RemovedInAirflow3Warning: Fetching SMTP credentials from configuration variables will be deprecated in a future release. Please set credentials using a connection instead.
  send_mime_email(e_from=mail_from, e_to=recipients, mime_msg=msg, conn_id=conn_id, dryrun=dryrun)

[2024-02-17T18:59:58.504+0000] {configuration.py:1046} WARNING - section/key [smtp/smtp_user] not found in config
[2024-02-17T18:59:58.504+0000] {email.py:270} INFO - Email alerting: attempt 1
[2024-02-17T18:59:58.510+0000] {taskinstance.py:2698} ERROR - Task failed with exception
Traceback (most recent call last):
  File "/home/airflow/.local/lib/python3.8/site-packages/airflow/models/taskinstance.py", line 433, in _execute_task
    result = execute_callable(context=context, **execute_callable_kwargs)
  File "/home/airflow/.local/lib/python3.8/site-packages/airflow/operators/email.py", line 79, in execute
    send_email(
  File "/home/airflow/.local/lib/python3.8/site-packages/airflow/utils/email.py", line 80, in send_email
    return backend(
  File "/home/airflow/.local/lib/python3.8/site-packages/airflow/utils/email.py", line 154, in send_email_smtp
    send_mime_email(e_from=mail_from, e_to=recipients, mime_msg=msg, conn_id=conn_id, dryrun=dryrun)
  File "/home/airflow/.local/lib/python3.8/site-packages/airflow/utils/email.py", line 272, in send_mime_email
    smtp_conn = _get_smtp_connection(smtp_host, smtp_port, smtp_timeout, smtp_ssl)
  File "/home/airflow/.local/lib/python3.8/site-packages/airflow/utils/email.py", line 316, in _get_smtp_connection
    return smtplib.SMTP(host=host, port=port, timeout=timeout)
  File "/usr/local/lib/python3.8/smtplib.py", line 255, in __init__
    (code, msg) = self.connect(host, port)
  File "/usr/local/lib/python3.8/smtplib.py", line 339, in connect
    self.sock = self._get_socket(host, port, self.timeout)
  File "/usr/local/lib/python3.8/smtplib.py", line 310, in _get_socket
    return socket.create_connection((host, port), timeout,
  File "/usr/local/lib/python3.8/socket.py", line 808, in create_connection
    raise err
  File "/usr/local/lib/python3.8/socket.py", line 796, in create_connection
    sock.connect(sa)
OSError: [Errno 99] Cannot assign requested address
[2024-02-17T18:59:58.526+0000] {taskinstance.py:1138} INFO - Marking task as UP_FOR_RETRY. dag_id=src_to_data_platform, task_id=email_on_failure, execution_date=20240217T185948, start_date=20240217T185958, end_date=20240217T185958
[2024-02-17T18:59:58.561+0000] {standard_task_runner.py:107} ERROR - Failed to execute job 56 for task email_on_failure ([Errno 99] Cannot assign requested address; 95)
[2024-02-17T18:59:58.588+0000] {local_task_job_runner.py:234} INFO - Task exited with return code 1
[2024-02-17T18:59:58.684+0000] {taskinstance.py:3280} INFO - 0 downstream tasks scheduled from follow-on schedule check
